Workbook

Sheet Summary
A2: Year-over-year cost escalation (%) | B2: 0.09 | C2: Average annual rate of inflation over the 10-year period
C3: TYPE 1 | D3: TYPE 2 | E3: TYPE 3 | F3: TYPE 4 | G3: Segregate facilities by up to 4 categories from a COST standpoint (e.g. hospitals, clinics, health outposts & labs & pharmacies…)
C4: =C5/B5 -> 0.0052114354 | D4: =D5/B5 -> 0.014740917 | E4: =E5/B5 -> 0.18418702 | F4: =F5/B5 -> 0.79586063
A5: Total # Facilities | B5: =C5+D5+E5+F5 -> 6716 | C5: 35 | D5: 99 | E5: 1237 | F5: 5345 | G5: Enter the number of facilites of each COST type.
A6: Annual facility growth rate (%) | B6: 0.025 | C6: The annual expansion rate of the number of facilities, expressed as a %
A7: Population size (#) | B7: 15100000 | C7: country population
A8: Annual population growth rate (%) | B8: 0.025
A9: # Health Workers | B9: 20605 | C9: The number of health workers across ALL cadres (doctors, nurses, pharmacists, CHWs…).
A10: HW population growth rate (%) | B10: 0.025 | C10: The annual expansion rate of the health workforce, expressed as a %
A12: Pre-Launch Costs | B12: =Governance!F38 -> 445000 | C12: This value is from the "Pre-Launch" column on the Governance tab; it indicates activities to be undertaken BEFORE implementing national digital health infrastructure
A14: Year | B14: 1 | C14: 2 | D14: 3 | E14: 4 | F14: 5 | G14: 6 | H14: 7 | I14: 8 | J14: 9 | K14: 10 | L14: 10-yr Total
A15: Governance | B15: =Governance!G35 -> 165000 | C15: =Governance!H35 -> 179850 | D15: =Governance!I35 -> 196036.5 | E15: =Governance!J35 -> 213679.79 | F15: =Governance!K35 -> 628153.82 | G15: =Governance!L35 -> 253872.95 | H15: =Governance!M35 -> 276721.52 | I15: =Governance!N35 -> 301626.45 | ... K15: =Governance!P35 -> 966492.51 | L15: =SUM(B15:K15) -> 3510206.4 | M15: =L15/$L$24 -> 0.025789495
A16: Datacentre infrastructure | B16: =Datacentre!B33 -> 740000 | C16: =Datacentre!C33 -> 261600 | D16: =Datacentre!D33 -> 285144 | E16: =Datacentre!E33 -> 310806.96 | F16: =Datacentre!F33 -> 338779.59 | G16: =Datacentre!G33 -> 369269.75 | H16: =Datacentre!H33 -> 402504.03 | I16: =Datacentre!I33 -> 438729.39 | ... K16: =Datacentre!K33 -> 521254.39 | L16: =SUM(B16:K16) -> 4146303.1 | M16: =L16/$L$24 -> 0.030462899
A17: Client Registry | B17: =CR!B27 -> 2029225 | C17: =CR!C27 -> 931444.79 | D17: =CR!D27 -> 1016223.4 | E17: =CR!E27 -> 1108743.3 | F17: =CR!F27 -> 1209714.3 | G17: =CR!G27 -> 2522230.7 | H17: =CR!H27 -> 1484815.5 | I17: =CR!I27 -> 1621316.5 | ... K17: =CR!K27 -> 1933357.8 | L17: =SUM(B17:K17) -> 15627510 | M17: =L17/$L$24 -> 0.11481535
A18: Facility Registry | B18: ='ILR-FR'!B18 -> 87160 | C18: ='ILR-FR'!C18 -> 78304.51 | D18: ='ILR-FR'!D18 -> 87396.606 | E18: ='ILR-FR'!E18 -> 97546.731 | F18: ='ILR-FR'!F18 -> 108878.22 | G18: ='ILR-FR'!G18 -> 121528.79 | H18: ='ILR-FR'!H18 -> 135652.26 | I18: ='ILR-FR'!I18 -> 151420.38 | ... K18: ='ILR-FR'!K18 -> 188680.27 | L18: =SUM(B18:K18) -> 1225592.7 | M18: =L18/$L$24 -> 0.0090044329
A19: Health Worker Registry | B19: ='ILR-HWR'!B18 -> 287260 | C19: ='ILR-HWR'!C18 -> 282791.23 | D19: ='ILR-HWR'!D18 -> 315770.29 | E19: ='ILR-HWR'!E18 -> 352600.1 | F19: ='ILR-HWR'!F18 -> 393730.73 | G19: ='ILR-HWR'!G18 -> 439664.86 | H19: ='ILR-HWR'!H18 -> 490964 | I19: ='ILR-HWR'!I18 -> 548255.33 | ... K19: ='ILR-HWR'!K18 -> 683698.66 | L19: =SUM(B19:K19) -> 4406974.6 | M19: =L19/$L$24 -> 0.032378053
A20: Shared Health Record | B20: =SHR!B53 -> 4387087.5 | C20: =SHR!C53 -> 5930994.5 | D20: =SHR!D53 -> 6683199 | E20: =SHR!E53 -> 8720805.1 | F20: =SHR!F53 -> 6394314 | G20: =SHR!G53 -> 7142604.9 | H20: =SHR!H53 -> 7978503 | I20: =SHR!I53 -> 8912268.7 | ... K20: =SHR!K53 -> 11120595 | L20: =SUM(B20:K20) -> 77225736 | M20: =L20/$L$24 -> 0.56737766
A21: Terminology Services | B21: =TS!B18 -> 290000 | C21: =TS!C18 -> 84475 | D21: =TS!D18 -> 92077.75 | E21: =TS!E18 -> 100364.75 | F21: =TS!F18 -> 109397.57 | G21: =TS!G18 -> 119243.36 | H21: =TS!H18 -> 129975.26 | I21: =TS!I18 -> 141673.03 | ... K21: =TS!K18 -> 168321.73 | L21: =SUM(B21:K21) -> 1389952.1 | M21: =L21/$L$24 -> 0.010211981
A22: HMIS | B22: =HMIS!B18 -> 855920 | C22: =HMIS!C18 -> 908589.12 | D22: =HMIS!D18 -> 1014898.4 | E22: =HMIS!E18 -> 1133652.4 | F22: =HMIS!F18 -> 1266308.5 | G22: =HMIS!G18 -> 1414494.7 | H22: =HMIS!H18 -> 1580029.8 | I22: =HMIS!I18 -> 1764945.5 | ... K22: =HMIS!K18 -> 2202264.3 | L22: =SUM(B22:K22) -> 14112614 | M22: =L22/$L$24 -> 0.10368541
A23: HHR Capacity-building | B23: ='HRH Capacity'!B25 -> 5751250 | C23: ='HRH Capacity'!C25 -> 1127966.1 | D23: ='HRH Capacity'!D25 -> 645378.33 | E23: ='HRH Capacity'!E25 -> 714573.8 | F23: ='HRH Capacity'!F25 -> 791299.67 | G23: ='HRH Capacity'!G25 -> 876386.43 | H23: ='HRH Capacity'!H25 -> 970757.24 | I23: ='HRH Capacity'!I25 -> 1075438.3 | ... K23: ='HRH Capacity'!K25 -> 1320422.9 | L23: =SUM(B23:K23) -> 14465043 | M23: =L23/$L$24 -> 0.10627471
A24: Total Annual Cost | B24: =SUM(B15:B23) -> 14592902 | C24: =SUM(C15:C23) -> 9786015.2 | D24: =SUM(D15:D23) -> 10336124 | E24: =SUM(E15:E23) -> 12752773 | F24: =SUM(F15:F23) -> 11240576 | G24: =SUM(G15:G23) -> 13259297 | H24: =SUM(H15:H23) -> 13449923 | I24: =SUM(I15:I23) -> 14955674 | ... M24: =SUM(M15:M23) -> 1
A25: Running total cost | B25: =B24 -> 14592902 | C25: =B25+C24 -> 24378918 | D25: =C25+D24 -> 34715042 | E25: =D25+E24 -> 47467815 | F25: =E25+F24 -> 58708391 | G25: =F25+G24 -> 71967688 | H25: =G25+H24 -> 85417611 | I25: =H25+I24 -> 1.0037328e+08 | J25: =I25+J24 -> 1.1700485e+08 | K25: =J25+K24 -> 1.3610993e+08
B26: =B24/$L$24 -> 0.10721409 | C26: =C24/$L$24 -> 0.071897877 | D26: =D24/$L$24 -> 0.07593953 | E26: =E24/$L$24 -> 0.093694654 | F26: =F24/$L$24 -> 0.082584542 | G26: =G24/$L$24 -> 0.097416083 | H26: =H24/$L$24 -> 0.098816614 | I26: =I24/$L$24 -> 0.10987937 | ... K26: =K24/$L$24 -> 0.14036512
A28: Annual total health expenditure (per capita $) | B28: 71 | C28: Enter the per-capita total health expenditure (THE, e.g. from WB stats page)
A29: 10-yr avg annual ICT cost per capita | B29: =K25/B7/10 -> 0.90139028 | C29: this is per capita
A30: ICT as a % of health expenditure | B30: =B29/(B28*L32/10) -> 0.0083562802 | C30: As a reasonableness test, ICT spend in many OECD countries is 2-5% of total health expenditure (THE)
B32: =(1+$B$2)^(B14-1) -> 1 | C32: =(1+$B$2)^(C14-1) -> 1.09 | D32: =(1+$B$2)^(D14-1) -> 1.1881 | E32: =(1+$B$2)^(E14-1) -> 1.295029 | F32: =(1+$B$2)^(F14-1) -> 1.4115816 | G32: =(1+$B$2)^(G14-1) -> 1.538624 | H32: =(1+$B$2)^(H14-1) -> 1.6771001 | I32: =(1+$B$2)^(I14-1) -> 1.8280391 | ... K32: =(1+$B$2)^(K14-1) -> 2.1718933 | L32: =SUM(B32:K32) -> 15.19293

Sheet Governance
A2: Year over year cost escalation (%) | B2: =Summary!B2 -> 0.09
G3: YEAR
B4: # | C4: Units | D4: Cost per Unit | E4: Extended Cost | F4: Pre-Launch | G4: 1 | H4: 2 | I4: 3 | J4: 4 | K4: 5 | L4: 6 | M4: 7 | N4: 8 | O4: 9 | P4: 10 | Q4: 10-year Cost | R4: % of total
A5: Digital Health Strategy | E5: Put a "1" for the years when this activity is to be done | F5: 1 | K5: 1 | P5: 1
A6: Subject Matter Experts | B6: 40 | C6: days | D6: 1000 | E6: =D6*B6 -> 40000
A7: Workshops | B7: 1 | C7: each | D7: 10000 | E7: =D7*B7 -> 10000
A8: Regional meetings | B8: 4 | C8: each | D8: 10000 | E8: =D8*B8 -> 40000
A9: Subtotal | E9: =SUM(E6:E8) -> 90000 | F9: =F5*$E$9 -> 90000 | G9: =G5*$E$9*(1+$B$2)^(G$4-1) -> 0 | H9: =H5*$E$9*(1+$B$2)^(H$4-1) -> 0 | I9: =I5*$E$9*(1+$B$2)^(I$4-1) -> 0 | J9: =J5*$E$9*(1+$B$2)^(J$4-1) -> 0 | K9: =K5*$E$9*(1+$B$2)^(K$4-1) -> 127042.34 | L9: =L5*$E$9*(1+$B$2)^(L$4-1) -> 0 | M9: =M5*$E$9*(1+$B$2)^(M$4-1) -> 0 | N9: =N5*$E$9*(1+$B$2)^(N$4-1) -> 0 | ... P9: =P5*$E$9*(1+$B$2)^(P$4-1) -> 195470.4 | Q9: =SUM(G9:P9) -> 322512.74 | R9: =Q9/$Q$35 -> 0.091878569
A11: Digital Health Blueprint | E11: Put a "1" for the years when this activity is to be done | F11: 1 | K11: 1 | P11: 1
A12: Subject Matter Experts | B12: 40 | C12: days | D12: 1000 | E12: =D12*B12 -> 40000
A13: Workshops | B13: 2 | C13: each | D13: 10000 | E13: =D13*B13 -> 20000
A14: Regional meetings | B14: 0 | C14: each | D14: 10000 | E14: =D14*B14 -> 0
A15: Subtotal | E15: =SUM(E12:E14) -> 60000 | F15: =F11*$E$15 -> 60000 | G15: =G11*$E$15*(1+$B$2)^(G$4-1) -> 0 | H15: =H11*$E$15*(1+$B$2)^(H$4-1) -> 0 | I15: =I11*$E$15*(1+$B$2)^(I$4-1) -> 0 | J15: =J11*$E$15*(1+$B$2)^(J$4-1) -> 0 | K15: =K11*$E$15*(1+$B$2)^(K$4-1) -> 84694.897 | L15: =L11*$E$15*(1+$B$2)^(L$4-1) -> 0 | M15: =M11*$E$15*(1+$B$2)^(M$4-1) -> 0 | N15: =N11*$E$15*(1+$B$2)^(N$4-1) -> 0 | ... P15: =P11*$E$15*(1+$B$2)^(P$4-1) -> 130313.6 | Q15: =SUM(G15:P15) -> 215008.49 | R15: =Q15/$Q$35 -> 0.06125238
A17: eHealth Norms and Standards | E17: Put a "1" for the years when this activity is to be done | F17: 1 | K17: 1 | P17: 1
A18: Subject Matter Experts | B18: 20 | C18: days | D18: 1000 | E18: =D18*B18 -> 20000
A19: Workshops | B19: 1 | C19: each | D19: 10000 | E19: =D19*B19 -> 10000
A20: Regional meetings | B20: 4 | C20: each | D20: 10000 | E20: =D20*B20 -> 40000
A21: Subtotal | E21: =SUM(E18:E20) -> 70000 | F21: =F17*$E$21 -> 70000 | G21: =G17*$E$21*(1+$B$2)^(G$4-1) -> 0 | H21: =H17*$E$21*(1+$B$2)^(H$4-1) -> 0 | I21: =I17*$E$21*(1+$B$2)^(I$4-1) -> 0 | J21: =J17*$E$21*(1+$B$2)^(J$4-1) -> 0 | K21: =K17*$E$21*(1+$B$2)^(K$4-1) -> 98810.713 | L21: =L17*$E$21*(1+$B$2)^(L$4-1) -> 0 | M21: =M17*$E$21*(1+$B$2)^(M$4-1) -> 0 | N21: =N17*$E$21*(1+$B$2)^(N$4-1) -> 0 | ... P21: =P17*$E$21*(1+$B$2)^(P$4-1) -> 152032.53 | Q21: =SUM(G21:P21) -> 250843.24 | R21: =Q21/$Q$35 -> 0.07146111
A23: Health Data Sharing Policy | E23: Put a "1" for the years when this activity is to be done | F23: 1 | K23: 1 | P23: 1
A24: Subject Matter Experts | B24: 10 | C24: days | D24: 1000 | E24: =D24*B24 -> 10000
A25: Workshops | B25: 1 | C25: each | D25: 10000 | E25: =D25*B25 -> 10000
A26: Regional meetings | B26: 4 | C26: each | D26: 10000 | E26: =D26*B26 -> 40000
A27: Subtotal | E27: =SUM(E24:E26) -> 60000 | F27: =F23*$E$27 -> 60000 | G27: =G23*$E$27*(1+$B$2)^(G$4-1) -> 0 | H27: =H23*$E$27*(1+$B$2)^(H$4-1) -> 0 | I27: =I23*$E$27*(1+$B$2)^(I$4-1) -> 0 | J27: =J23*$E$27*(1+$B$2)^(J$4-1) -> 0 | K27: =K23*$E$27*(1+$B$2)^(K$4-1) -> 84694.897 | L27: =L23*$E$27*(1+$B$2)^(L$4-1) -> 0 | M27: =M23*$E$27*(1+$B$2)^(M$4-1) -> 0 | N27: =N23*$E$27*(1+$B$2)^(N$4-1) -> 0 | ... P27: =P23*$E$27*(1+$B$2)^(P$4-1) -> 130313.6 | Q27: =SUM(G27:P27) -> 215008.49 | R27: =Q27/$Q$35 -> 0.06125238
A29: Digital Health Governance | D29: Annual cost/unit | E29: Annual costs | F29: 1 | G29: 1 | H29: 1 | I29: 1 | J29: 1 | K29: 1 | L29: 1 | M29: 1 | N29: 1 | O29: 1 | P29: 1
A30: Committees | B30: 1 | C30: department | D30: 100000 | E30: =D30*B30 -> 100000
A31: Regular meetings | B31: 50 | C31: meetings | D31: 100 | E31: =D31*B31 -> 5000
A32: National meetings | B32: 4 | C32: meetings | D32: 15000 | E32: =D32*B32 -> 60000
A33: Subtotal | E33: =SUM(E30:E32) -> 165000 | F33: =F29*$E$33 -> 165000 | G33: =G29*$E$33*(1+$B$2)^(G$4-1) -> 165000 | H33: =H29*$E$33*(1+$B$2)^(H$4-1) -> 179850 | I33: =I29*$E$33*(1+$B$2)^(I$4-1) -> 196036.5 | J33: =J29*$E$33*(1+$B$2)^(J$4-1) -> 213679.79 | K33: =K29*$E$33*(1+$B$2)^(K$4-1) -> 232910.97 | L33: =L29*$E$33*(1+$B$2)^(L$4-1) -> 253872.95 | M33: =M29*$E$33*(1+$B$2)^(M$4-1) -> 276721.52 | N33: =N29*$E$33*(1+$B$2)^(N$4-1) -> 301626.45 | ... P33: =P29*$E$33*(1+$B$2)^(P$4-1) -> 358362.39 | Q33: =SUM(G33:P33) -> 2506833.4 | R33: =Q33/$Q$35 -> 0.71415556
F35: Annual Cost (including escalation) | G35: =G9+G15+G21+G27+G33 -> 165000 | H35: =H9+H15+H21+H27+H33 -> 179850 | I35: =I9+I15+I21+I27+I33 -> 196036.5 | J35: =J9+J15+J21+J27+J33 -> 213679.79 | K35: =K9+K15+K21+K27+K33 -> 628153.82 | L35: =L9+L15+L21+L27+L33 -> 253872.95 | M35: =M9+M15+M21+M27+M33 -> 276721.52 | N35: =N9+N15+N21+N27+N33 -> 301626.45 | ... P35: =P9+P15+P21+P27+P33 -> 966492.51 | Q35: =SUM(G35:P35) -> 3510206.4 | R35: =SUM(R9:R34) -> 1
F36: Running total cost | G36: =G35 -> 165000 | H36: =G36+H35 -> 344850 | I36: =H36+I35 -> 540886.5 | J36: =I36+J35 -> 754566.29 | K36: =J36+K35 -> 1382720.1 | L36: =K36+L35 -> 1636593.1 | M36: =L36+M35 -> 1913314.6 | N36: =M36+N35 -> 2214941 | O36: =N36+O35 -> 2543713.9 | P36: =O36+P35 -> 3510206.4
E38: Pre-Launch costs: | F38: =F33+F27+F21+F15+F9 -> 445000

Sheet Datacentre
A2: IT installer rate ($/hr) | C2: Hourly rate for infrastructure application consultants (e.g. international consultants)
A3: IT operator rate ($/hr) | C3: Hourly rate for local country IT operators for datacentre
A4: Software maintenance fee (% of license fee) | C4: Annual maintenance fee for software (e.g. commercial software is typically 15% annual maint. fee)
A6: Year-over-year cost escalation (%) | B6: =Summary!B2 -> 0.09
B8: Software fee ($) | C8: VM fee ($) | D8: IT Effort (hrs) | E8: Extended cost ($) | F8: For datacentre installation, enter 1-time costs for the SETUP and INSTALLATION
A9: Datacentre Installation (1-time costs)
A10: Client Registry (CR) | E10: =B10+C10+(D10*$B$2) -> 0
A11: Health Worker Registry (ILR-HWR) | E11: =B11+C11+(D11*$B$2) -> 0
A12: Facility Registry (ILR-FR) | E12: =B12+C12+(D12*$B$2) -> 0
A13: Terminology Server (TS) | E13: =B13+C13+(D13*$B$2) -> 0
A14: Shared Health Record Repository (SHR) | E14: =B14+C14+(D14*$B$2) -> 0
A15: Health Management Information System (HMIS) | E15: =B15+C15+(D15*$B$2) -> 0
A16: Interoperability Layer (IL) | E16: =B16+C16+(D16*$B$2) -> 0
A17: "All in" one-time setup cost ($) | B17: 500000 | E17: =B17+C17+(D17*$B$2) -> 500000 | F17: ** either enter an all-in cost or enter installation costs for each infrastructure actor (not both)
B18: =SUM(B10:B17) -> 500000 | C18: =SUM(C10:C17) -> 0 | D18: =SUM(D10:D17) -> 0 | E18: =SUM(E10:E17) -> 500000
B20: Software fee ($) | C20: VM fee ($) | D20: IT Effort (hrs) | E20: Extended cost ($)
A21: Datacentre Operation (monthly costs) | F21: For datacentre operation, enter monthly fees for Virtual Machines (VMs) and for ongoing SUPPORT
A22: Client Registry (CR) | B22: =B10*$B$4/12 -> 0 | E22: =B22+C22+(D22*$B$3) -> 0
A23: Health Worker Registry (ILR-HWR) | B23: =B11*$B$4/12 -> 0 | E23: =B23+C23+(D23*$B$3) -> 0
A24: Facility Registry (ILR-FR) | B24: =B12*$B$4/12 -> 0 | E24: =B24+C24+(D24*$B$3) -> 0
A25: Terminology Server (TS) | B25: =B13*$B$4/12 -> 0 | E25: =B25+C25+(D25*$B$3) -> 0
A26: Shared Health Record Repository (SHR) | B26: =B14*$B$4/12 -> 0 | E26: =B26+C26+(D26*$B$3) -> 0
A27: Health Management Information System (HMIS) | B27: =B15*$B$4/12 -> 0 | E27: =B27+C27+(D27*$B$3) -> 0
A28: Interoperability Layer (IL) | B28: =B16*$B$4/12 -> 0 | E28: =B28+C28+(D28*$B$3) -> 0
A29: "All in" infrastructure monthly operating cost ($) | B29: 20000 | E29: =B29+C29+(D29*$B$3) -> 20000 | F29: ** either enter an all-in monthly cost or enter monthly support costs for each infrastructure actor (not both)
B30: =SUM(B22:B29) -> 20000 | C30: =SUM(C22:C29) -> 0 | D30: =SUM(D22:D29) -> 0 | E30: =SUM(E22:E29) -> 20000
A32: Year | B32: 1 | C32: 2 | D32: 3 | E32: 4 | F32: 5 | G32: 6 | H32: 7 | I32: 8 | J32: 9 | K32: 10
A33: Annual Cost (including escalation) | B33: =$E$18+($E$30*12) -> 740000 | C33: =$E$30*12*(1+$B$6)^(C32-1) -> 261600 | D33: =$E$30*12*(1+$B$6)^(D32-1) -> 285144 | E33: =$E$30*12*(1+$B$6)^(E32-1) -> 310806.96 | F33: =$E$30*12*(1+$B$6)^(F32-1) -> 338779.59 | G33: =$E$30*12*(1+$B$6)^(G32-1) -> 369269.75 | H33: =$E$30*12*(1+$B$6)^(H32-1) -> 402504.03 | I33: =$E$30*12*(1+$B$6)^(I32-1) -> 438729.39 | J33: =$E$30*12*(1+$B$6)^(J32-1) -> 478215.03 | K33: =$E$30*12*(1+$B$6)^(K32-1) -> 521254.39
A34: Running Total Cost | B34: =B33 -> 740000 | C34: =B34+C33 -> 1001600 | D34: =C34+D33 -> 1286744 | E34: =D34+E33 -> 1597551 | F34: =E34+F33 -> 1936330.5 | G34: =F34+G33 -> 2305600.3 | H34: =G34+H33 -> 2708104.3 | I34: =H34+I33 -> 3146833.7 | J34: =I34+J33 -> 3625048.7 | K34: =J34+K33 -> 4146303.1

Sheet CR
A2: Initial Population size (#) | B2: =Summary!B7 -> 15100000
A3: Population growth rate (%) | B3: =Summary!B8 -> 0.025
A5: Digital ID provisioning cost ($/ea) | B5: 0.01 | C5: The cost of establishing a unique digital ID for health (e.g. ID confirmation, PKI certificate, etc.)
A6: ID card provisioning cost ($/ea) | B6: 0.05 | C6: The cost per card could be low (e.g. $0.02 for barcode sticker, $0.15 per cardboard card) or high ($5 per plastic card with a chip and a picture)
A7: ID card renewal period (yrs) | B7: 5 | C7: Enter the "valid for" time period, after which the cards will need to be renewed (e.g. 5 years is typical for a "picture" card)
A8: ID card churn rate (%/yr) | B8: 0.01 | C8: Percentage of cards per year that will need to be regenerated because they were lost or damaged, etc.
A10: ID issuing facilities (#) | B10: 1371 | C10: How many facilities will be able to issue cards?
A11: ID establishment setup cost ($) | B11: 200 | C11: What will be setup cost per facility (e.g. will they need photo equipment, or a plastic card printer, or only a laminator)?
A12: ID establishment operating cost ($/mo.) | B12: 50 | C12: What will be the incremental added monthly cost needed to support card issuing at this facility?
A14: Year-over-year cost escalation (%) | B14: =Summary!$B$2 -> 0.09
A16: Initial proportion that need digital IDs (%) | B16: 1 | C16: What proportion of the population need their digital ID established (e.g. do not already have one that can be used)?
A17: Proportion that need cards (%) | B17: 1 | C17: What proportion of the population are going to need a "wallet" ID for health? (if everyone, use 100%)
A19: Year | B19: 1 | C19: 2 | D19: 3 | E19: 4 | F19: 5 | G19: 6 | H19: 7 | I19: 8 | J19: 9 | K19: 10 | L19: 10-year total | M19: % of total
A20: Population (#) | B20: =$B$2*(1+$B$3)^(B19-1) -> 15100000 | C20: =$B$2*(1+$B$3)^(C19-1) -> 15477500 | D20: =$B$2*(1+$B$3)^(D19-1) -> 15864437 | E20: =$B$2*(1+$B$3)^(E19-1) -> 16261048 | F20: =$B$2*(1+$B$3)^(F19-1) -> 16667575 | G20: =$B$2*(1+$B$3)^(G19-1) -> 17084264 | H20: =$B$2*(1+$B$3)^(H19-1) -> 17511371 | I20: =$B$2*(1+$B$3)^(I19-1) -> 17949155 | ... K20: =$B$2*(1+$B$3)^(K19-1) -> 18857831
A21: Population with ID cards (#) | B21: =B20*$B$17 -> 15100000 | C21: =C20*$B$17 -> 15477500 | D21: =D20*$B$17 -> 15864437 | E21: =E20*$B$17 -> 16261048 | F21: =F20*$B$17 -> 16667575 | G21: =G20*$B$17 -> 17084264 | H21: =H20*$B$17 -> 17511371 | I21: =I20*$B$17 -> 17949155 | ... K21: =K20*$B$17 -> 18857831
A22: New ID cards issued (#) | B22: =B21+IF(B20*$B$3>0,B20*$B$3,0)+(B21*$B$8) -> 15628500 | C22: =IF(C21-B21>0,C21-B21,0)+(C21*$B$8) -> 532275 | D22: =IF(D21-C21>0,D21-C21,0)+(D21*$B$8) -> 545581.88 | E22: =IF(E21-D21>0,E21-D21,0)+(E21*$B$8) -> 559221.42 | F22: =IF(F21-E21>0,F21-E21,0)+(F21*$B$8) -> 573201.96 | G22: =IF(G21-F21>0,G21-F21,0)+(G21*$B$8) -> 587532.01 | H22: =IF(H21-G21>0,H21-G21,0)+(H21*$B$8) -> 602220.31 | I22: =IF(I21-H21>0,I21-H21,0)+(I21*$B$8) -> 617275.81 | J22: =IF(J21-I21>0,J21-I21,0)+(J21*$B$8) -> 632707.71 | K22: =IF(K21-J21>0,K21-J21,0)+(K21*$B$8) -> 648525.4
A23: IDs cards renewed (#) | C23: =IF(C19>$B$7,OFFSET(C23,-1,-$B$7,1,1)+OFFSET(C23,0,-$B$7,1,1),0) -> 0 | D23: =IF(D19>$B$7,OFFSET(D23,-1,-$B$7,1,1)+OFFSET(D23,0,-$B$7,1,1),0) -> 0 | E23: =IF(E19>$B$7,OFFSET(E23,-1,-$B$7,1,1)+OFFSET(E23,0,-$B$7,1,1),0) -> 0 | F23: =IF(F19>$B$7,OFFSET(F23,-1,-$B$7,1,1)+OFFSET(F23,0,-$B$7,1,1),0) -> 0 | G23: =IF(G19>$B$7,OFFSET(G23,-1,-$B$7,1,1)+OFFSET(G23,0,-$B$7,1,1),0) -> 15628500 | H23: =IF(H19>$B$7,OFFSET(H23,-1,-$B$7,1,1)+OFFSET(H23,0,-$B$7,1,1),0) -> 532275 | I23: =IF(I19>$B$7,OFFSET(I23,-1,-$B$7,1,1)+OFFSET(I23,0,-$B$7,1,1),0) -> 545581.88 | J23: =IF(J19>$B$7,OFFSET(J23,-1,-$B$7,1,1)+OFFSET(J23,0,-$B$7,1,1),0) -> 559221.42 | K23: =IF(K19>$B$7,OFFSET(K23,-1,-$B$7,1,1)+OFFSET(K23,0,-$B$7,1,1),0) -> 573201.96
A24: Digital IDs provisioned (#) | B24: =B2*B16 -> 15100000 | C24: =C22 -> 532275 | D24: =D22 -> 545581.88 | E24: =E22 -> 559221.42 | F24: =F22 -> 573201.96 | G24: =G22 -> 587532.01 | H24: =H22 -> 602220.31 | I24: =I22 -> 617275.81 | J24: =J22 -> 632707.71 | K24: =K22 -> 648525.4
A25: ID issuing facility costs ($) | B25: =B10*B11+B10*B12*12 -> 1096800 | C25: =$B$10*$B$12*12*(1+$B$14)^(C19-1) -> 896634 | D25: =$B$10*$B$12*12*(1+$B$14)^(D19-1) -> 977331.06 | E25: =$B$10*$B$12*12*(1+$B$14)^(E19-1) -> 1065290.9 | F25: =$B$10*$B$12*12*(1+$B$14)^(F19-1) -> 1161167 | G25: =$B$10*$B$12*12*(1+$B$14)^(G19-1) -> 1265672.1 | H25: =$B$10*$B$12*12*(1+$B$14)^(H19-1) -> 1379582.6 | I25: =$B$10*$B$12*12*(1+$B$14)^(I19-1) -> 1503745 | J25: =$B$10*$B$12*12*(1+$B$14)^(J19-1) -> 1639082 | K25: =$B$10*$B$12*12*(1+$B$14)^(K19-1) -> 1786599.4 | L25: =SUM(B25:K25) -> 12771904 | M25: =L25/K28 -> 0.81727056
A26: ID card issuing costs ($) | B26: =(B22+B23)*($B$6) + B24*$B$5 -> 932425 | C26: =((C22+C23)*$B$6 + C24*$B$5)*(1+$B$14)^(C19-1) -> 34810.785 | D26: =((D22+D23)*$B$6 + D24*$B$5)*(1+$B$14)^(D19-1) -> 38892.35 | E26: =((E22+E23)*$B$6 + E24*$B$5)*(1+$B$14)^(E19-1) -> 43452.478 | F26: =((F22+F23)*$B$6 + F24*$B$5)*(1+$B$14)^(F19-1) -> 48547.281 | G26: =((G22+G23)*$B$6 + G24*$B$5)*(1+$B$14)^(G19-1) -> 1256558.7 | H26: =((H22+H23)*$B$6 + H24*$B$5)*(1+$B$14)^(H19-1) -> 105232.95 | I26: =((I22+I23)*$B$6 + I24*$B$5)*(1+$B$14)^(I19-1) -> 117571.51 | J26: =((J22+J23)*$B$6 + J24*$B$5)*(1+$B$14)^(J19-1) -> 131356.77 | K26: =((K22+K23)*$B$6 + K24*$B$5)*(1+$B$14)^(K19-1) -> 146758.35 | L26: =SUM(B26:K26) -> 2855606.1 | M26: =L26/K28 -> 0.18272944
A27: Annual Cost (including escalation) | B27: =B25+B26 -> 2029225 | C27: =C25+C26 -> 931444.79 | D27: =D25+D26 -> 1016223.4 | E27: =E25+E26 -> 1108743.3 | F27: =F25+F26 -> 1209714.3 | G27: =G25+G26 -> 2522230.7 | H27: =H25+H26 -> 1484815.5 | I27: =I25+I26 -> 1621316.5 | ... K27: =K25+K26 -> 1933357.8 | L27: =SUM(B27:K27) -> 15627510 | M27: =L27/K28 -> 1
A28: Running total Costs | B28: =B27 -> 2029225 | C28: =B28+C27 -> 2960669.8 | D28: =C28+D27 -> 3976893.2 | E28: =D28+E27 -> 5085636.5 | F28: =E28+F27 -> 6295350.8 | G28: =F28+G27 -> 8817581.6 | H28: =G28+H27 -> 10302397 | I28: =H28+I27 -> 11923714 | J28: =I28+J27 -> 13694152 | K28: =J28+K27 -> 15627510

Sheet ILR-FR
A1: NOTE: it is assumed that a facility registry based on a federation of underlying data sources is being deployed (similar to OpenHIE's inter-linked registry).
A2: Facility databases (#) | B2: 2 | C2: How many underlying databases will contain facility data (e.g. DHIS2 database, military facility list, etc.)?
A3: Cost per database application interface ($) | B3: 10000 | C3: What will it cost to connect each database to the InterLinked Registry?
A4: API maintenance cost per year (%) | B4: 0.15 | C4: What will be the annual maintenance fee (as a %) to support each database interface?
A6: Year-over-year cost escalation (%) | B6: =Summary!$B$2 -> 0.09
A8: Public and private care facilities (#) | B8: =Summary!B5 -> 6716
A9: Annual growth rate (%) | B9: =Summary!B6 -> 0.025
A10: MOH interactions per facility per year (#) | B10: 2 | C10: The data must be kept accurate and fresh; how many times each year will MOH contact each facility to confirm/refresh data?
A11: Cost per interaction ($) | B11: 5 | C11: What will each "refresh" cost (e.g. $.10 per SMS, $5 per phone call, $50 per in-person visit)?
A13: Year | B13: 1 | C13: 2 | D13: 3 | E13: 4 | F13: 5 | G13: 6 | H13: 7 | I13: 8 | J13: 9 | K13: 10 | L13: 10-year total | M13: % of total
A14: Facilities (#) | B14: =B8 -> 6716 | C14: =B14*(1+$B$9) -> 6883.9 | D14: =C14*(1+$B$9) -> 7055.9975 | E14: =D14*(1+$B$9) -> 7232.3974 | F14: =E14*(1+$B$9) -> 7413.2074 | G14: =F14*(1+$B$9) -> 7598.5376 | H14: =G14*(1+$B$9) -> 7788.501 | I14: =H14*(1+$B$9) -> 7983.2135 | J14: =I14*(1+$B$9) -> 8182.7939 | K14: =J14*(1+$B$9) -> 8387.3637
A15: MOH Interactions | B15: =B14*$B$10 -> 13432 | C15: =C14*$B$10 -> 13767.8 | D15: =D14*$B$10 -> 14111.995 | E15: =E14*$B$10 -> 14464.795 | F15: =F14*$B$10 -> 14826.415 | G15: =G14*$B$10 -> 15197.075 | H15: =H14*$B$10 -> 15577.002 | I15: =I14*$B$10 -> 15966.427 | ... K15: =K14*$B$10 -> 16774.727
A16: Interaction costs | B16: =B15*$B$11 -> 67160 | C16: =C15*$B$11*(1+$B$6)^(C$13-1) -> 75034.51 | D16: =D15*$B$11*(1+$B$6)^(D$13-1) -> 83832.306 | E16: =E15*$B$11*(1+$B$6)^(E$13-1) -> 93661.644 | F16: =F15*$B$11*(1+$B$6)^(F$13-1) -> 104643.47 | G16: =G15*$B$11*(1+$B$6)^(G$13-1) -> 116912.92 | H16: =H15*$B$11*(1+$B$6)^(H$13-1) -> 130620.96 | I16: =I15*$B$11*(1+$B$6)^(I$13-1) -> 145936.27 | J16: =J15*$B$11*(1+$B$6)^(J$13-1) -> 163047.29 | K16: =K15*$B$11*(1+$B$6)^(K$13-1) -> 182164.59 | L16: =SUM(B16:K16) -> 1163014 | M16: =L16/K19 -> 0.94893998
A17: Database API costs | B17: =B2*B3 -> 20000 | C17: =$B$17*$B$4*(1+$B$6)^(C$13-1) -> 3270 | D17: =$B$17*$B$4*(1+$B$6)^(D$13-1) -> 3564.3 | E17: =$B$17*$B$4*(1+$B$6)^(E$13-1) -> 3885.087 | F17: =$B$17*$B$4*(1+$B$6)^(F$13-1) -> 4234.7448 | G17: =$B$17*$B$4*(1+$B$6)^(G$13-1) -> 4615.8719 | H17: =$B$17*$B$4*(1+$B$6)^(H$13-1) -> 5031.3003 | I17: =$B$17*$B$4*(1+$B$6)^(I$13-1) -> 5484.1174 | J17: =$B$17*$B$4*(1+$B$6)^(J$13-1) -> 5977.6879 | K17: =$B$17*$B$4*(1+$B$6)^(K$13-1) -> 6515.6798 | L17: =SUM(B17:K17) -> 62578.789 | M17: =L17/K19 -> 0.051060019
A18: Annual Cost (including escalation) | B18: =B16+B17 -> 87160 | C18: =(C16+C17) -> 78304.51 | D18: =(D16+D17) -> 87396.606 | E18: =(E16+E17) -> 97546.731 | F18: =(F16+F17) -> 108878.22 | G18: =(G16+G17) -> 121528.79 | H18: =(H16+H17) -> 135652.26 | I18: =(I16+I17) -> 151420.38 | J18: =(J16+J17) -> 169024.98 | K18: =(K16+K17) -> 188680.27 | L18: =SUM(B18:K18) -> 1225592.7 | M18: =L18/K19 -> 1
A19: Running total Costs | B19: =B18 -> 87160 | C19: =B19+C18 -> 165464.51 | D19: =C19+D18 -> 252861.12 | E19: =D19+E18 -> 350407.85 | F19: =E19+F18 -> 459286.06 | G19: =F19+G18 -> 580814.86 | H19: =G19+H18 -> 716467.11 | I19: =H19+I18 -> 867887.5 | J19: =I19+J18 -> 1036912.5 | K19: =J19+K18 -> 1225592.7

Sheet ILR-HWR
A1: NOTE: it is assumed that a health workder registry based on a federation of underlying data sources is being deployed (similar to OpenHIE's inter-linked registry).
A2: Health Worker Cadre databases (#) | B2: 4 | C2: How many underlying databases will contain health worker data (e.g. College of Physicians, College of Nurses, MOH payroll system, etc.)?
A3: Cost per database application interface ($) | B3: 10000 | C3: What will it cost to connect each database to the InterLinked Registry?
A4: API maintenance cost per year (%) | B4: 0.15 | C4: What will be the annual maintenance fee (as a %) to support each database interface?
A6: Year-over-year cost escalation (%) | B6: =Summary!$B$2 -> 0.09
A8: Initial HW population (#) | B8: =Summary!B9 -> 20605
A9: Annual growth rate (%) | B9: =Summary!B10 -> 0.025
A10: MOH interactions per HW per year (#) | B10: 12 | C10: The data must be kept accurate and fresh; how many times each year will MOH contact each health worker to confirm/refresh data?
A11: Cost per interaction ($) | B11: 1 | C11: What will each "refresh" cost (e.g. $.10 per SMS, $5 per phone call, $50 per in-person visit)?
A13: Year | B13: 1 | C13: 2 | D13: 3 | E13: 4 | F13: 5 | G13: 6 | H13: 7 | I13: 8 | J13: 9 | K13: 10 | L13: 10-year total | M13: % of total
A14: HW Population (#) | B14: =B8 -> 20605 | C14: =B14*(1+$B$9) -> 21120.125 | D14: =C14*(1+$B$9) -> 21648.128 | E14: =D14*(1+$B$9) -> 22189.331 | F14: =E14*(1+$B$9) -> 22744.065 | G14: =F14*(1+$B$9) -> 23312.666 | H14: =G14*(1+$B$9) -> 23895.483 | I14: =H14*(1+$B$9) -> 24492.87 | J14: =I14*(1+$B$9) -> 25105.192 | K14: =J14*(1+$B$9) -> 25732.821
A15: MOH Interactions | B15: =B14*$B$10 -> 247260 | C15: =C14*$B$10 -> 253441.5 | D15: =D14*$B$10 -> 259777.54 | E15: =E14*$B$10 -> 266271.98 | F15: =F14*$B$10 -> 272928.78 | G15: =G14*$B$10 -> 279751.99 | H15: =H14*$B$10 -> 286745.79 | I15: =I14*$B$10 -> 293914.44 | ... K15: =K14*$B$10 -> 308793.86
A16: Interaction costs | B16: =B15*$B$11 -> 247260 | C16: =C15*$B$11*(1+$B$6)^(C$13-1) -> 276251.23 | D16: =D15*$B$11*(1+$B$6)^(D$13-1) -> 308641.69 | E16: =E15*$B$11*(1+$B$6)^(E$13-1) -> 344829.93 | F16: =F15*$B$11*(1+$B$6)^(F$13-1) -> 385261.24 | G16: =G15*$B$11*(1+$B$6)^(G$13-1) -> 430433.12 | H16: =H15*$B$11*(1+$B$6)^(H$13-1) -> 480901.4 | I16: =I15*$B$11*(1+$B$6)^(I$13-1) -> 537287.09 | J16: =J15*$B$11*(1+$B$6)^(J$13-1) -> 600284.01 | K16: =K15*$B$11*(1+$B$6)^(K$13-1) -> 670667.3 | L16: =SUM(B16:K16) -> 4281817 | M16: =L16/K19 -> 0.97160011
A17: Database interface costs | B17: =B2*B3 -> 40000 | C17: =$B$17*$B$4*(1+$B$6)^(C$13-1) -> 6540 | D17: =$B$17*$B$4*(1+$B$6)^(D$13-1) -> 7128.6 | E17: =$B$17*$B$4*(1+$B$6)^(E$13-1) -> 7770.174 | F17: =$B$17*$B$4*(1+$B$6)^(F$13-1) -> 8469.4897 | G17: =$B$17*$B$4*(1+$B$6)^(G$13-1) -> 9231.7437 | H17: =$B$17*$B$4*(1+$B$6)^(H$13-1) -> 10062.601 | I17: =$B$17*$B$4*(1+$B$6)^(I$13-1) -> 10968.235 | J17: =$B$17*$B$4*(1+$B$6)^(J$13-1) -> 11955.376 | K17: =$B$17*$B$4*(1+$B$6)^(K$13-1) -> 13031.36 | L17: =SUM(B17:K17) -> 125157.58 | M17: =L17/K19 -> 0.028399886
A18: Annual Cost (including escalation) | B18: =B16+B17 -> 287260 | C18: =(C16+C17) -> 282791.23 | D18: =(D16+D17) -> 315770.29 | E18: =(E16+E17) -> 352600.1 | F18: =(F16+F17) -> 393730.73 | G18: =(G16+G17) -> 439664.86 | H18: =(H16+H17) -> 490964 | I18: =(I16+I17) -> 548255.33 | J18: =(J16+J17) -> 612239.38 | K18: =(K16+K17) -> 683698.66 | L18: =SUM(B18:K18) -> 4406974.6 | M18: =L18/K19 -> 1
A19: Running total Costs | B19: =B18 -> 287260 | C19: =B19+C18 -> 570051.23 | D19: =C19+D18 -> 885821.53 | E19: =D19+E18 -> 1238421.6 | F19: =E19+F18 -> 1632152.4 | G19: =F19+G18 -> 2071817.2 | H19: =G19+H18 -> 2562781.2 | I19: =H19+I18 -> 3111036.6 | J19: =I19+J18 -> 3723275.9 | K19: =J19+K18 -> 4406974.6

Sheet SHR
A2: Unique health ICT applications (#) | B2: 10 | C2: How many unique point of service software systems (EMRs, mHealth apps, lab, etc.) need to be interfaced to the Interopability Layer?
A3: Cost per application interface ($) | B3: 25000 | C3: What will be the cost, per POS, to develop the full suite of necessary interfaces (e.g. PIX, PDQ, XDS, etc.)?
A4: API maintenance cost per year (%) | B4: 0.15 | C4: What will be annual support cost for each interface (as a % of original dev cost)?
A6: Year-over-year cost escalation (%) | B6: =Summary!$B$2 -> 0.09
A8: Facilities (from Summary sheet) (#) | B8: ='ILR-FR'!B8 -> 6716 | C8: TYPE 1 | D8: TYPE 2 | E8: TYPE 3 | F8: TYPE 4
A9: Facilities of this TYPE (%) | C9: =Summary!C4 -> 0.0052114354 | D9: =Summary!D4 -> 0.014740917 | E9: =Summary!E4 -> 0.18418702 | F9: =1-E9-D9-C9 -> 0.79586063
A10: Facilities of this TYPE (#) | C10: =Summary!C5 -> 35 | D10: =Summary!D5 -> 99 | E10: =Summary!E5 -> 1237 | F10: =Summary!F5 -> 5345
A11: Facilities for which MOH pays (%) | C11: 1 | D11: 1 | E11: 1 | F11: 1 | G11: What proportion of the facilities are MOH-supported (vs private sector)?
A12: MOH-supported facilities (#) | C12: =C10*C11 -> 35 | D12: =D10*D11 -> 99 | E12: =E10*E11 -> 1237 | F12: =F10*F11 -> 5345
A13: 1-time ICT implementation cost for TYPE ($) | C13: 50000 | D13: 10000 | E13: 2000 | F13: 1000 | G13: What is the implementation cost for a POS at each type of facility (e.g. EMR implementation cost)?
A14: Annual ICT operating cost for TYPE ($) | C14: 12000 | D14: 1200 | E14: 1200 | F14: 300 | G14: What is the annual operating cost for the POS at this facility type (e.g. IT support plus internet cost, etc.)?
A15: Current ICT adoption by this TYPE (%) | C15: 0 | D15: 0 | E15: 0 | F15: 0 | G15: How many MOH-supported facilities of each type already HAVE eHealth systems in place?
A16: Current ICT-capable by this TYPE (#) | C16: =C10*C15*C11 -> 0 | D16: =D10*D15*D11 -> 0 | E16: =E10*E15*E11 -> 0 | F16: =F10*F15*F11 -> 0
A17: ICT rollout period (yrs) | C17: 2 | D17: 4 | E17: 4 | F17: 4 | G17: How many years will it take to do a rollout to all facilities?
A18: MOH interactions per year (#) | C18: 1 | D18: 1 | E18: 1 | F18: 4 | G18: How many times per year will MOH "interact" with each installation (e.g. to confirm security, refresh code lists, etc.)?
A19: MOH cost per interaction ($) | C19: 200 | D19: 100 | E19: 50 | F19: 5 | G19: What will it cost per audit (e.g. $.10 for SMS, $5 for phone call, $50 for onsite visit)?
A21: Year | B21: 1 | C21: 2 | D21: 3 | E21: 4 | F21: 5 | G21: 6 | H21: 7 | I21: 8 | J21: 9 | K21: 10
A22: Total Facilities (from ILR-FR sheet) (#) | B22: ='ILR-FR'!B14 -> 6716 | C22: ='ILR-FR'!C14 -> 6883.9 | D22: ='ILR-FR'!D14 -> 7055.9975 | E22: ='ILR-FR'!E14 -> 7232.3974 | F22: ='ILR-FR'!F14 -> 7413.2074 | G22: ='ILR-FR'!G14 -> 7598.5376 | H22: ='ILR-FR'!H14 -> 7788.501 | I22: ='ILR-FR'!I14 -> 7983.2135 | ... K22: ='ILR-FR'!K14 -> 8387.3637
A23: TYPE 1 Facilities MOH pays for (#) | B23: =B22*$C$9*$C$11 -> 35 | C23: =C22*$C$9*$C$11 -> 35.875 | D23: =D22*$C$9*$C$11 -> 36.771875 | E23: =E22*$C$9*$C$11 -> 37.691172 | F23: =F22*$C$9*$C$11 -> 38.633451 | G23: =G22*$C$9*$C$11 -> 39.599287 | H23: =H22*$C$9*$C$11 -> 40.58927 | I23: =I22*$C$9*$C$11 -> 41.604001 | ... K23: =K22*$C$9*$C$11 -> 43.710204
A24: TYPE 1 Facilities with ICT (#) | B24: =IF($C$16+(IF(B21>$C$17,1,B21/$C$17)*((B22*$C$9*$C$11)-$C$16))>B23,B23,$C$16+(IF(B21>$C$17,1,B21/$C$17)*((B22*$C$9*$C$11)-$C$16))) -> 17.5 | C24: =IF($C$16+(IF(C21>$C$17,1,C21/$C$17)*((C22*$C$9*$C$11)-$C$16))>C23,C23,$C$16+(IF(C21>$C$17,1,C21/$C$17)*((C22*$C$9*$C$11)-$C$16))) -> 35.875 | D24: =IF($C$16+(IF(D21>$C$17,1,D21/$C$17)*((D22*$C$9*$C$11)-$C$16))>D23,D23,$C$16+(IF(D21>$C$17,1,D21/$C$17)*((D22*$C$9*$C$11)-$C$16))) -> 36.771875 | E24: =IF($C$16+(IF(E21>$C$17,1,E21/$C$17)*((E22*$C$9*$C$11)-$C$16))>E23,E23,$C$16+(IF(E21>$C$17,1,E21/$C$17)*((E22*$C$9*$C$11)-$C$16))) -> 37.691172 | F24: =IF($C$16+(IF(F21>$C$17,1,F21/$C$17)*((F22*$C$9*$C$11)-$C$16))>F23,F23,$C$16+(IF(F21>$C$17,1,F21/$C$17)*((F22*$C$9*$C$11)-$C$16))) -> 38.633451 | G24: =IF($C$16+(IF(G21>$C$17,1,G21/$C$17)*((G22*$C$9*$C$11)-$C$16))>G23,G23,$C$16+(IF(G21>$C$17,1,G21/$C$17)*((G22*$C$9*$C$11)-$C$16))) -> 39.599287 | H24: =IF($C$16+(IF(H21>$C$17,1,H21/$C$17)*((H22*$C$9*$C$11)-$C$16))>H23,H23,$C$16+(IF(H21>$C$17,1,H21/$C$17)*((H22*$C$9*$C$11)-$C$16))) -> 40.58927 | I24: =IF($C$16+(IF(I21>$C$17,1,I21/$C$17)*((I22*$C$9*$C$11)-$C$16))>I23,I23,$C$16+(IF(I21>$C$17,1,I21/$C$17)*((I22*$C$9*$C$11)-$C$16))) -> 41.604001 | ... K24: =IF($C$16+(IF(K21>$C$17,1,K21/$C$17)*((K22*$C$9*$C$11)-$C$16))>K23,K23,$C$16+(IF(K21>$C$17,1,K21/$C$17)*((K22*$C$9*$C$11)-$C$16))) -> 43.710204
A25: TYPE 1 new (1-time) ICT costs | B25: =(B24-C16)*C13 -> 875000 | C25: =(C24-B24)*$C$13 -> 918750 | D25: =(D24-C24)*$C$13 -> 44843.75 | E25: =(E24-D24)*$C$13 -> 45964.844 | F25: =(F24-E24)*$C$13 -> 47113.965 | G25: =(G24-F24)*$C$13 -> 48291.814 | H25: =(H24-G24)*$C$13 -> 49499.109 | I25: =(I24-H24)*$C$13 -> 50736.587 | J25: =(J24-I24)*$C$13 -> 52005.002 | K25: =(K24-J24)*$C$13 -> 53305.127
A26: TYPE 1 operating costs | B26: =B24*$C$14 -> 210000 | C26: =C24*$C$14 -> 430500 | D26: =D24*$C$14 -> 441262.5 | E26: =E24*$C$14 -> 452294.06 | F26: =F24*$C$14 -> 463601.41 | G26: =G24*$C$14 -> 475191.45 | H26: =H24*$C$14 -> 487071.24 | I26: =I24*$C$14 -> 499248.02 | ... K26: =K24*$C$14 -> 524522.45
A27: TYPE 1 MOH interactions (#) | B27: =B24*$C$18 -> 17.5 | C27: =C24*$C$18 -> 35.875 | D27: =D24*$C$18 -> 36.771875 | E27: =E24*$C$18 -> 37.691172 | F27: =F24*$C$18 -> 38.633451 | G27: =G24*$C$18 -> 39.599287 | H27: =H24*$C$18 -> 40.58927 | I27: =I24*$C$18 -> 41.604001 | ... K27: =K24*$C$18 -> 43.710204
A28: TYPE 1 interaction costs | B28: =B27*$C$19 -> 3500 | C28: =C27*$C$19 -> 7175 | D28: =D27*$C$19 -> 7354.375 | E28: =E27*$C$19 -> 7538.2344 | F28: =F27*$C$19 -> 7726.6902 | G28: =G27*$C$19 -> 7919.8575 | H28: =H27*$C$19 -> 8117.8539 | I28: =I27*$C$19 -> 8320.8003 | ... K28: =K27*$C$19 -> 8742.0408
A29: TYPE 2 Facilities MOH pays for (#) | B29: =B22*$D$9*$D$11 -> 99 | C29: =C22*$D$9*$D$11 -> 101.475 | D29: =D22*$D$9*$D$11 -> 104.01187 | E29: =E22*$D$9*$D$11 -> 106.61217 | F29: =F22*$D$9*$D$11 -> 109.27748 | G29: =G22*$D$9*$D$11 -> 112.00941 | H29: =H22*$D$9*$D$11 -> 114.80965 | I29: =I22*$D$9*$D$11 -> 117.67989 | ... K29: =K22*$D$9*$D$11 -> 123.63743
A30: TYPE 2 Facilities with ICT (#) | B30: =IF($D$16+(IF(B21>$D$17,1,B21/$D$17)*((B22*$D$9*$D$11)-$D$16))>B29,B29,$D$16+(IF(B21>$D$17,1,B21/$D$17)*((B22*$D$9*$D$11)-$D$16))) -> 24.75 | C30: =IF($D$16+(IF(C21>$D$17,1,C21/$D$17)*((C22*$D$9*$D$11)-$D$16))>C29,C29,$D$16+(IF(C21>$D$17,1,C21/$D$17)*((C22*$D$9*$D$11)-$D$16))) -> 50.7375 | D30: =IF($D$16+(IF(D21>$D$17,1,D21/$D$17)*((D22*$D$9*$D$11)-$D$16))>D29,D29,$D$16+(IF(D21>$D$17,1,D21/$D$17)*((D22*$D$9*$D$11)-$D$16))) -> 78.008906 | E30: =IF($D$16+(IF(E21>$D$17,1,E21/$D$17)*((E22*$D$9*$D$11)-$D$16))>E29,E29,$D$16+(IF(E21>$D$17,1,E21/$D$17)*((E22*$D$9*$D$11)-$D$16))) -> 106.61217 | F30: =IF($D$16+(IF(F21>$D$17,1,F21/$D$17)*((F22*$D$9*$D$11)-$D$16))>F29,F29,$D$16+(IF(F21>$D$17,1,F21/$D$17)*((F22*$D$9*$D$11)-$D$16))) -> 109.27748 | G30: =IF($D$16+(IF(G21>$D$17,1,G21/$D$17)*((G22*$D$9*$D$11)-$D$16))>G29,G29,$D$16+(IF(G21>$D$17,1,G21/$D$17)*((G22*$D$9*$D$11)-$D$16))) -> 112.00941 | H30: =IF($D$16+(IF(H21>$D$17,1,H21/$D$17)*((H22*$D$9*$D$11)-$D$16))>H29,H29,$D$16+(IF(H21>$D$17,1,H21/$D$17)*((H22*$D$9*$D$11)-$D$16))) -> 114.80965 | I30: =IF($D$16+(IF(I21>$D$17,1,I21/$D$17)*((I22*$D$9*$D$11)-$D$16))>I29,I29,$D$16+(IF(I21>$D$17,1,I21/$D$17)*((I22*$D$9*$D$11)-$D$16))) -> 117.67989 | ... K30: =IF($D$16+(IF(K21>$D$17,1,K21/$D$17)*((K22*$D$9*$D$11)-$D$16))>K29,K29,$D$16+(IF(K21>$D$17,1,K21/$D$17)*((K22*$D$9*$D$11)-$D$16))) -> 123.63743
A31: TYPE 2 new (1-time) ICT costs | B31: =(B30-D16)*D13 -> 247500 | C31: =(C30-B30)*$D$13 -> 259875 | D31: =(D30-C30)*$D$13 -> 272714.06 | E31: =(E30-D30)*$D$13 -> 286032.66 | F31: =(F30-E30)*$D$13 -> 26653.043 | G31: =(G30-F30)*$D$13 -> 27319.369 | H31: =(H30-G30)*$D$13 -> 28002.353 | I31: =(I30-H30)*$D$13 -> 28702.412 | J31: =(J30-I30)*$D$13 -> 29419.972 | K31: =(K30-J30)*$D$13 -> 30155.472
A32: TYPE 2 operating costs | B32: =B30*$D$14 -> 29700 | C32: =C30*$D$14 -> 60885 | D32: =D30*$D$14 -> 93610.687 | E32: =E30*$D$14 -> 127934.61 | F32: =F30*$D$14 -> 131132.97 | G32: =G30*$D$14 -> 134411.3 | H32: =H30*$D$14 -> 137771.58 | I32: =I30*$D$14 -> 141215.87 | ... K32: =K30*$D$14 -> 148364.92
A33: TYPE 2 MOH interactions (#) | B33: =B30*$D$18 -> 24.75 | C33: =C30*$D$18 -> 50.7375 | D33: =D30*$D$18 -> 78.008906 | E33: =E30*$D$18 -> 106.61217 | F33: =F30*$D$18 -> 109.27748 | G33: =G30*$D$18 -> 112.00941 | H33: =H30*$D$18 -> 114.80965 | I33: =I30*$D$18 -> 117.67989 | ... K33: =K30*$D$18 -> 123.63743
A34: TYPE 2 interaction costs | B34: =B33*$D$19 -> 2475 | C34: =C33*$D$19 -> 5073.75 | D34: =D33*$D$19 -> 7800.8906 | E34: =E33*$D$19 -> 10661.217 | F34: =F33*$D$19 -> 10927.748 | G34: =G33*$D$19 -> 11200.941 | H34: =H33*$D$19 -> 11480.965 | I34: =I33*$D$19 -> 11767.989 | ... K34: =K33*$D$19 -> 12363.743
A35: TYPE 3 Facilities MOH pays for (#) | B35: =B22*$E$9*$E$11 -> 1237 | C35: =C22*$E$9*$E$11 -> 1267.925 | D35: =D22*$E$9*$E$11 -> 1299.6231 | E35: =E22*$E$9*$E$11 -> 1332.1137 | F35: =F22*$E$9*$E$11 -> 1365.4165 | G35: =G22*$E$9*$E$11 -> 1399.552 | H35: =H22*$E$9*$E$11 -> 1434.5408 | I35: =I22*$E$9*$E$11 -> 1470.4043 | ... K35: =K22*$E$9*$E$11 -> 1544.8435
A36: TYPE 3 Facilities with ICT (#) | B36: =IF($E$16+(IF(B21>$E$17,1,B21/$E$17)*((B22*$E$9*$E$11)-$E$16))>B35,B35,$E$16+(IF(B21>$E$17,1,B21/$E$17)*((B22*$E$9*$E$11)-$E$16))) -> 309.25 | C36: =IF($E$16+(IF(C21>$E$17,1,C21/$E$17)*((C22*$E$9*$E$11)-$E$16))>C35,C35,$E$16+(IF(C21>$E$17,1,C21/$E$17)*((C22*$E$9*$E$11)-$E$16))) -> 633.9625 | D36: =IF($E$16+(IF(D21>$E$17,1,D21/$E$17)*((D22*$E$9*$E$11)-$E$16))>D35,D35,$E$16+(IF(D21>$E$17,1,D21/$E$17)*((D22*$E$9*$E$11)-$E$16))) -> 974.71734 | E36: =IF($E$16+(IF(E21>$E$17,1,E21/$E$17)*((E22*$E$9*$E$11)-$E$16))>E35,E35,$E$16+(IF(E21>$E$17,1,E21/$E$17)*((E22*$E$9*$E$11)-$E$16))) -> 1332.1137 | F36: =IF($E$16+(IF(F21>$E$17,1,F21/$E$17)*((F22*$E$9*$E$11)-$E$16))>F35,F35,$E$16+(IF(F21>$E$17,1,F21/$E$17)*((F22*$E$9*$E$11)-$E$16))) -> 1365.4165 | G36: =IF($E$16+(IF(G21>$E$17,1,G21/$E$17)*((G22*$E$9*$E$11)-$E$16))>G35,G35,$E$16+(IF(G21>$E$17,1,G21/$E$17)*((G22*$E$9*$E$11)-$E$16))) -> 1399.552 | H36: =IF($E$16+(IF(H21>$E$17,1,H21/$E$17)*((H22*$E$9*$E$11)-$E$16))>H35,H35,$E$16+(IF(H21>$E$17,1,H21/$E$17)*((H22*$E$9*$E$11)-$E$16))) -> 1434.5408 | I36: =IF($E$16+(IF(I21>$E$17,1,I21/$E$17)*((I22*$E$9*$E$11)-$E$16))>I35,I35,$E$16+(IF(I21>$E$17,1,I21/$E$17)*((I22*$E$9*$E$11)-$E$16))) -> 1470.4043 | ... K36: =IF($E$16+(IF(K21>$E$17,1,K21/$E$17)*((K22*$E$9*$E$11)-$E$16))>K35,K35,$E$16+(IF(K21>$E$17,1,K21/$E$17)*((K22*$E$9*$E$11)-$E$16))) -> 1544.8435
A37: TYPE 3 new (1-time) ICT costs | B37: =(B36-E16)*E13 -> 618500 | C37: =(C36-B36)*$E$13 -> 649425 | D37: =(D36-C36)*$E$13 -> 681509.69 | E37: =(E36-D36)*$E$13 -> 714792.72 | F37: =(F36-E36)*$E$13 -> 66605.685 | G37: =(G36-F36)*$E$13 -> 68270.827 | H37: =(H36-G36)*$E$13 -> 69977.598 | I37: =(I36-H36)*$E$13 -> 71727.038 | J37: =(J36-I36)*$E$13 -> 73520.214 | K37: =(K36-J36)*$E$13 -> 75358.219
A38: TYPE 3 operating costs | B38: =B36*$E$14 -> 371100 | C38: =C36*$E$14 -> 760755 | D38: =D36*$E$14 -> 1169660.8 | E38: =E36*$E$14 -> 1598536.4 | F38: =F36*$E$14 -> 1638499.9 | G38: =G36*$E$14 -> 1679462.4 | H38: =H36*$E$14 -> 1721448.9 | I38: =I36*$E$14 -> 1764485.1 | ... K38: =K36*$E$14 -> 1853812.2
A39: TYPE 3 MOH interactions (#) | B39: =B36*$E$18 -> 309.25 | C39: =C36*$E$18 -> 633.9625 | D39: =D36*$E$18 -> 974.71734 | E39: =E36*$E$18 -> 1332.1137 | F39: =F36*$E$18 -> 1365.4165 | G39: =G36*$E$18 -> 1399.552 | H39: =H36*$E$18 -> 1434.5408 | I39: =I36*$E$18 -> 1470.4043 | ... K39: =K36*$E$18 -> 1544.8435
A40: TYPE 3 interaction costs | B40: =B39*$E$19 -> 15462.5 | C40: =C39*$E$19 -> 31698.125 | D40: =D39*$E$19 -> 48735.867 | E40: =E39*$E$19 -> 66605.685 | F40: =F39*$E$19 -> 68270.827 | G40: =G39*$E$19 -> 69977.598 | H40: =H39*$E$19 -> 71727.038 | I40: =I39*$E$19 -> 73520.214 | ... K40: =K39*$E$19 -> 77242.175
A41: TYPE 4 Facilities MOH pays for (#) | B41: =B22*$F$9*$F$11 -> 5345 | C41: =C22*$F$9*$F$11 -> 5478.625 | D41: =D22*$F$9*$F$11 -> 5615.5906 | E41: =E22*$F$9*$F$11 -> 5755.9804 | F41: =F22*$F$9*$F$11 -> 5899.8799 | G41: =G22*$F$9*$F$11 -> 6047.3769 | H41: =H22*$F$9*$F$11 -> 6198.5613 | I41: =I22*$F$9*$F$11 -> 6353.5254 | ... K41: =K22*$F$9*$F$11 -> 6675.1726
A42: TYPE 4 Facilities with ICT (#) | B42: =IF($F$16+(IF(B21>$F$17,1,B21/$F$17)*((B22*$F$9*$F$11)-$F$16))>B41,B41,$F$16+(IF(B21>$F$17,1,B21/$F$17)*((B22*$F$9*$F$11)-$F$16))) -> 1336.25 | C42: =IF($F$16+(IF(C21>$F$17,1,C21/$F$17)*((C22*$F$9*$F$11)-$F$16))>C41,C41,$F$16+(IF(C21>$F$17,1,C21/$F$17)*((C22*$F$9*$F$11)-$F$16))) -> 2739.3125 | D42: =IF($F$16+(IF(D21>$F$17,1,D21/$F$17)*((D22*$F$9*$F$11)-$F$16))>D41,D41,$F$16+(IF(D21>$F$17,1,D21/$F$17)*((D22*$F$9*$F$11)-$F$16))) -> 4211.693 | E42: =IF($F$16+(IF(E21>$F$17,1,E21/$F$17)*((E22*$F$9*$F$11)-$F$16))>E41,E41,$F$16+(IF(E21>$F$17,1,E21/$F$17)*((E22*$F$9*$F$11)-$F$16))) -> 5755.9804 | F42: =IF($F$16+(IF(F21>$F$17,1,F21/$F$17)*((F22*$F$9*$F$11)-$F$16))>F41,F41,$F$16+(IF(F21>$F$17,1,F21/$F$17)*((F22*$F$9*$F$11)-$F$16))) -> 5899.8799 | G42: =IF($F$16+(IF(G21>$F$17,1,G21/$F$17)*((G22*$F$9*$F$11)-$F$16))>G41,G41,$F$16+(IF(G21>$F$17,1,G21/$F$17)*((G22*$F$9*$F$11)-$F$16))) -> 6047.3769 | H42: =IF($F$16+(IF(H21>$F$17,1,H21/$F$17)*((H22*$F$9*$F$11)-$F$16))>H41,H41,$F$16+(IF(H21>$F$17,1,H21/$F$17)*((H22*$F$9*$F$11)-$F$16))) -> 6198.5613 | I42: =IF($F$16+(IF(I21>$F$17,1,I21/$F$17)*((I22*$F$9*$F$11)-$F$16))>I41,I41,$F$16+(IF(I21>$F$17,1,I21/$F$17)*((I22*$F$9*$F$11)-$F$16))) -> 6353.5254 | ... K42: =IF($F$16+(IF(K21>$F$17,1,K21/$F$17)*((K22*$F$9*$F$11)-$F$16))>K41,K41,$F$16+(IF(K21>$F$17,1,K21/$F$17)*((K22*$F$9*$F$11)-$F$16))) -> 6675.1726
A43: TYPE 4 new (1-time) ICT costs | B43: =(B42-F16)*F13 -> 1336250 | C43: =(C42-B42)*$F$13 -> 1403062.5 | D43: =(D42-C42)*$F$13 -> 1472380.5 | E43: =(E42-D42)*$F$13 -> 1544287.4 | F43: =(F42-E42)*$F$13 -> 143899.51 | G43: =(G42-F42)*$F$13 -> 147497 | H43: =(H42-G42)*$F$13 -> 151184.42 | I43: =(I42-H42)*$F$13 -> 154964.03 | J43: =(J42-I42)*$F$13 -> 158838.13 | K43: =(K42-J42)*$F$13 -> 162809.09
A44: TYPE 4 operating costs | B44: =B42*$F$14 -> 400875 | C44: =C42*$F$14 -> 821793.75 | D44: =D42*$F$14 -> 1263507.9 | E44: =E42*$F$14 -> 1726794.1 | F44: =F42*$F$14 -> 1769964 | G44: =G42*$F$14 -> 1814213.1 | H44: =H42*$F$14 -> 1859568.4 | I44: =I42*$F$14 -> 1906057.6 | ... K44: =K42*$F$14 -> 2002551.8
...

Sheet TS
A2: Terminology servers (#) | B2: 1
A3: Total cost of codelist databases ($) | B3: 250000 | C3: What is the one-time fee for licensing codelists (e.g. SNOMED-CT, ICD-10, LOINC, CPT, etc.)?
A4: Codelist maintenance cost per year (%) | B4: 0.15 | C4: What is the annual maintenance fee for the codelists (expressed as a % of purchase fee)?
A6: Year-over-year cost escalation (%) | B6: =Summary!$B$2 -> 0.09
A8: # of software applications (from SHR sheet) | B8: =SHR!B2 -> 10
A9: Annual growth rate (%) | B9: 0
A10: MOH interactions per app per year (#) | B10: 4 | C10: How many times per year will MOH "refresh" the codelists in the POS applications?
A11: Cost per interaction ($) | B11: 1000 | C11: How much will it cost for each codelist refresh (including POS conformance testing)?
A13: Year | B13: 1 | C13: 2 | D13: 3 | E13: 4 | F13: 5 | G13: 6 | H13: 7 | I13: 8 | J13: 9 | K13: 10 | L13: 10-year total | M13: % of total
A14: Health ICT applications (#) | B14: =B8 -> 10 | C14: =B14*(1+$B$9) -> 10 | D14: =C14*(1+$B$9) -> 10 | E14: =D14*(1+$B$9) -> 10 | F14: =E14*(1+$B$9) -> 10 | G14: =F14*(1+$B$9) -> 10 | H14: =G14*(1+$B$9) -> 10 | I14: =H14*(1+$B$9) -> 10 | J14: =I14*(1+$B$9) -> 10 | K14: =J14*(1+$B$9) -> 10
A15: MOH Interactions | B15: =B14*$B$10 -> 40 | C15: =C14*$B$10 -> 40 | D15: =D14*$B$10 -> 40 | E15: =E14*$B$10 -> 40 | F15: =F14*$B$10 -> 40 | G15: =G14*$B$10 -> 40 | H15: =H14*$B$10 -> 40 | I15: =I14*$B$10 -> 40 | ... K15: =K14*$B$10 -> 40
A16: Interaction costs | B16: =B15*$B$11 -> 40000 | C16: =C15*$B$11*(1+$B$6)^(C$13-1) -> 43600 | D16: =D15*$B$11*(1+$B$6)^(D$13-1) -> 47524 | E16: =E15*$B$11*(1+$B$6)^(E$13-1) -> 51801.16 | F16: =F15*$B$11*(1+$B$6)^(F$13-1) -> 56463.264 | G16: =G15*$B$11*(1+$B$6)^(G$13-1) -> 61544.958 | H16: =H15*$B$11*(1+$B$6)^(H$13-1) -> 67084.004 | I16: =I15*$B$11*(1+$B$6)^(I$13-1) -> 73121.565 | J16: =J15*$B$11*(1+$B$6)^(J$13-1) -> 79702.506 | K16: =K15*$B$11*(1+$B$6)^(K$13-1) -> 86875.731 | L16: =SUM(B16:K16) -> 607717.19 | M16: =L16/$K$19 -> 0.43722169
A17: Codelist costs | B17: =B2*B3 -> 250000 | C17: =$B$17*$B$4*(1+$B$6)^(C$13-1) -> 40875 | D17: =$B$17*$B$4*(1+$B$6)^(D$13-1) -> 44553.75 | E17: =$B$17*$B$4*(1+$B$6)^(E$13-1) -> 48563.588 | F17: =$B$17*$B$4*(1+$B$6)^(F$13-1) -> 52934.31 | G17: =$B$17*$B$4*(1+$B$6)^(G$13-1) -> 57698.398 | H17: =$B$17*$B$4*(1+$B$6)^(H$13-1) -> 62891.254 | I17: =$B$17*$B$4*(1+$B$6)^(I$13-1) -> 68551.467 | J17: =$B$17*$B$4*(1+$B$6)^(J$13-1) -> 74721.099 | K17: =$B$17*$B$4*(1+$B$6)^(K$13-1) -> 81445.998 | L17: =SUM(B17:K17) -> 782234.86 | M17: =L17/$K$19 -> 0.56277831
A18: Annual Cost (including escalation) | B18: =B16+B17 -> 290000 | C18: =(C16+C17) -> 84475 | D18: =(D16+D17) -> 92077.75 | E18: =(E16+E17) -> 100364.75 | F18: =(F16+F17) -> 109397.57 | G18: =(G16+G17) -> 119243.36 | H18: =(H16+H17) -> 129975.26 | I18: =(I16+I17) -> 141673.03 | J18: =(J16+J17) -> 154423.6 | K18: =(K16+K17) -> 168321.73 | L18: =SUM(B18:K18) -> 1389952.1 | M18: =L18/$K$19 -> 1
A19: Running total Costs | B19: =B18 -> 290000 | C19: =B19+C18 -> 374475 | D19: =C19+D18 -> 466552.75 | E19: =D19+E18 -> 566917.5 | F19: =E19+F18 -> 676315.07 | G19: =F19+G18 -> 795558.43 | H19: =G19+H18 -> 925533.69 | I19: =H19+I18 -> 1067206.7 | J19: =I19+J18 -> 1221630.3 | K19: =J19+K18 -> 1389952.1

Sheet HMIS
A2: HMIS databases (#) | B2: 2 | C2: How many HMIS data warehouses will need to be maintained (e.g. one for MOH, one for health insurer, etc.)?
A3: Cost per SHR-HMIS interface ($) | B3: 25000 | C3: What will it cost to connect the SHR to each database?
A4: API maintenance cost per year (%) | B4: 0.15 | C4: What will be the annual maintenance fee (as a %) to support each database interface?
A6: Year-over-year cost escalation (%) | B6: =Summary!$B$2 -> 0.09
A8: # Facilities (from ILR-FR sheet) | B8: ='ILR-FR'!B8 -> 6716
A9: Annual growth rate (from ILR-FR sheet) | B9: ='ILR-FR'!B9 -> 0.025
A10: HMIS data collections per facility per year (#) | B10: 12 | C10: In addition to the SHR data feed, how many times per year will each facility need to upload "tally sheet" data to the HMIS?
A11: Cost per interaction ($) | B11: 10 | C11: What will each upload cost (e.g. labour cost plus transmission cost per tally and upload)?
A13: Year | B13: 1 | C13: 2 | D13: 3 | E13: 4 | F13: 5 | G13: 6 | H13: 7 | I13: 8 | J13: 9 | K13: 10 | L13: 10-year total | M13: % of total
A14: Facilities (#) | B14: =B8 -> 6716 | C14: =B14*(1+$B$9) -> 6883.9 | D14: =C14*(1+$B$9) -> 7055.9975 | E14: =D14*(1+$B$9) -> 7232.3974 | F14: =E14*(1+$B$9) -> 7413.2074 | G14: =F14*(1+$B$9) -> 7598.5376 | H14: =G14*(1+$B$9) -> 7788.501 | I14: =H14*(1+$B$9) -> 7983.2135 | J14: =I14*(1+$B$9) -> 8182.7939 | K14: =J14*(1+$B$9) -> 8387.3637
A15: Data collection Interactions (#) | B15: =B14*$B$10 -> 80592 | C15: =C14*$B$10 -> 82606.8 | D15: =D14*$B$10 -> 84671.97 | E15: =E14*$B$10 -> 86788.769 | F15: =F14*$B$10 -> 88958.488 | G15: =G14*$B$10 -> 91182.451 | H15: =H14*$B$10 -> 93462.012 | I15: =I14*$B$10 -> 95798.562 | ... K15: =K14*$B$10 -> 100648.36
A16: Interaction costs ($) | B16: =B15*$B$11 -> 805920 | C16: =C15*$B$11*(1+$B$6)^(C$13-1) -> 900414.12 | D16: =D15*$B$11*(1+$B$6)^(D$13-1) -> 1005987.7 | E16: =E15*$B$11*(1+$B$6)^(E$13-1) -> 1123939.7 | F16: =F15*$B$11*(1+$B$6)^(F$13-1) -> 1255721.7 | G16: =G15*$B$11*(1+$B$6)^(G$13-1) -> 1402955 | H16: =H15*$B$11*(1+$B$6)^(H$13-1) -> 1567451.5 | I16: =I15*$B$11*(1+$B$6)^(I$13-1) -> 1751235.2 | J16: =J15*$B$11*(1+$B$6)^(J$13-1) -> 1956567.5 | K16: =K15*$B$11*(1+$B$6)^(K$13-1) -> 2185975.1 | L16: =SUM(B16:K16) -> 13956168 | M16: =L16/$K$19 -> 0.98891439
A17: Database API costs ($) | B17: =B2*B3 -> 50000 | C17: =$B$2*$B$3*$B$4*(1+$B$6)^(C$13-1) -> 8175 | D17: =$B$2*$B$3*$B$4*(1+$B$6)^(D$13-1) -> 8910.75 | E17: =$B$2*$B$3*$B$4*(1+$B$6)^(E$13-1) -> 9712.7175 | F17: =$B$2*$B$3*$B$4*(1+$B$6)^(F$13-1) -> 10586.862 | G17: =$B$2*$B$3*$B$4*(1+$B$6)^(G$13-1) -> 11539.68 | H17: =$B$2*$B$3*$B$4*(1+$B$6)^(H$13-1) -> 12578.251 | I17: =$B$2*$B$3*$B$4*(1+$B$6)^(I$13-1) -> 13710.293 | J17: =$B$2*$B$3*$B$4*(1+$B$6)^(J$13-1) -> 14944.22 | K17: =$B$2*$B$3*$B$4*(1+$B$6)^(K$13-1) -> 16289.2 | L17: =SUM(B17:K17) -> 156446.97 | M17: =L17/$K$19 -> 0.011085612
A18: Annual Cost (including escalation) | B18: =B16+B17 -> 855920 | C18: =(C16+C17) -> 908589.12 | D18: =(D16+D17) -> 1014898.4 | E18: =(E16+E17) -> 1133652.4 | F18: =(F16+F17) -> 1266308.5 | G18: =(G16+G17) -> 1414494.7 | H18: =(H16+H17) -> 1580029.8 | I18: =(I16+I17) -> 1764945.5 | J18: =(J16+J17) -> 1971511.7 | K18: =(K16+K17) -> 2202264.3 | L18: =SUM(B18:K18) -> 14112614 | M18: =L18/$K$19 -> 1
A19: Running total Costs | B19: =B18 -> 855920 | C19: =B19+C18 -> 1764509.1 | D19: =C19+D18 -> 2779407.5 | E19: =D19+E18 -> 3913060 | F19: =E19+F18 -> 5179368.5 | G19: =F19+G18 -> 6593863.2 | H19: =G19+H18 -> 8173893 | I19: =H19+I18 -> 9938838.5 | J19: =I19+J18 -> 11910350 | K19: =J19+K18 -> 14112614

Sheet HRH Capacity
A1: NOTE: it is assumed that there will be three main areas of digital health capacity-building investment:
A2: 1. Education regarding data use (each health worker, HW)
A3: 2. Training regarding solution software use (each facility) NOTE: this cost is included in the per-facility costs on the SHR tab
A4: 3. Degree-granting academic programmes in health informatics (each degree-granting programme)
A6: Year-over-year cost escalation (%) | B6: =Summary!B2 -> 0.09
A8: Initial cost: HW education in data use ($/HW) | B8: 250 | C8: Cost per HW of in-person or online course in data use
A9: Annual refresher cost: HW education in data use ($/HW) | B9: 10 | C9: Cost per HW of in-person or online annual refresher course
A10: Setup cost: academic HI programme ($/institution) | B10: 500000 | C10: Cost to establish a new health informatics curriculum at an academic institution
A11: Annual cost (net): academic HI programme ($/institution) | B11: 100000 | C11: Annual cost, net of student tuition fees, of operating the HI programme
A14: Year | B14: 1 | C14: 2 | D14: 3 | E14: 4 | F14: 5 | G14: 6 | H14: 7 | I14: 8 | J14: 9 | K14: 10 | L14: 10-yr Total | M14: % of total
A15: HW to receive initial data use education (#) | B15: ='ILR-HWR'!B14 -> 20605 | C15: ='ILR-HWR'!C14-'ILR-HWR'!B14 -> 515.125 | D15: ='ILR-HWR'!D14-'ILR-HWR'!C14 -> 528.00312 | E15: ='ILR-HWR'!E14-'ILR-HWR'!D14 -> 541.2032 | F15: ='ILR-HWR'!F14-'ILR-HWR'!E14 -> 554.73328 | G15: ='ILR-HWR'!G14-'ILR-HWR'!F14 -> 568.60162 | H15: ='ILR-HWR'!H14-'ILR-HWR'!G14 -> 582.81666 | I15: ='ILR-HWR'!I14-'ILR-HWR'!H14 -> 597.38707 | J15: ='ILR-HWR'!J14-'ILR-HWR'!I14 -> 612.32175 | K15: ='ILR-HWR'!K14-'ILR-HWR'!J14 -> 627.62979
A16: HW to receive refresher data use education (#) | B16: 0 | C16: =B16+B15 -> 20605 | D16: =C16+C15 -> 21120.125 | E16: =D16+D15 -> 21648.128 | F16: =E16+E15 -> 22189.331 | G16: =F16+F15 -> 22744.065 | H16: =G16+G15 -> 23312.666 | I16: =H16+H15 -> 23895.483 | J16: =I16+I15 -> 24492.87 | K16: =J16+J15 -> 25105.192
B17: Insert, for each year, the number of new academic programmes to be launched
A18: New academic programme introduced (#) | B18: 1 | C18: 1
A19: Running total of academic HI programmes (#) | B19: =B18 -> 1 | C19: =B19+C18 -> 2 | D19: =C19+D18 -> 2 | E19: =D19+E18 -> 2 | F19: =E19+F18 -> 2 | G19: =F19+G18 -> 2 | H19: =G19+H18 -> 2 | I19: =H19+I18 -> 2 | J19: =I19+J18 -> 2 | K19: =J19+K18 -> 2
A21: HW data use education - initial ($) | B21: =B15*$B$8 -> 5151250 | C21: =C15*$B$8*(1+$B$6)^(C$14-1) -> 140371.56 | D21: =D15*$B$8*(1+$B$6)^(D$14-1) -> 156830.13 | E21: =E15*$B$8*(1+$B$6)^(E$14-1) -> 175218.46 | F21: =F15*$B$8*(1+$B$6)^(F$14-1) -> 195762.83 | G21: =G15*$B$8*(1+$B$6)^(G$14-1) -> 218716.02 | H21: =H15*$B$8*(1+$B$6)^(H$14-1) -> 244360.47 | I21: =I15*$B$8*(1+$B$6)^(I$14-1) -> 273011.73 | J21: =J15*$B$8*(1+$B$6)^(J$14-1) -> 305022.36 | K21: =K15*$B$8*(1+$B$6)^(K$14-1) -> 340786.23 | L21: =SUM(B21:K21) -> 7201329.8 | M21: =L21/$K$26 -> 0.49784364
A22: HW data use education - refresher ($) | B22: =B16*$B$9 -> 0 | C22: =C16*$B$9*(1+$B$6)^(C$14-1) -> 224594.5 | D22: =D16*$B$9*(1+$B$6)^(D$14-1) -> 250928.21 | E22: =E16*$B$9*(1+$B$6)^(E$14-1) -> 280349.54 | F22: =F16*$B$9*(1+$B$6)^(F$14-1) -> 313220.52 | G22: =G16*$B$9*(1+$B$6)^(G$14-1) -> 349945.63 | H22: =H16*$B$9*(1+$B$6)^(H$14-1) -> 390976.75 | I22: =I16*$B$9*(1+$B$6)^(I$14-1) -> 436818.78 | J22: =J16*$B$9*(1+$B$6)^(J$14-1) -> 488035.78 | K22: =K16*$B$9*(1+$B$6)^(K$14-1) -> 545257.97 | L22: =SUM(B22:K22) -> 3280127.7 | M22: =L22/$K$26 -> 0.22676238
A23: Academic programme - setup ($) | B23: =B18*$B$10 -> 500000 | C23: =C18*$B$10*(1+$B$6)^(C$14-1) -> 545000 | D23: =D18*$B$10*(1+$B$6)^(D$14-1) -> 0 | E23: =E18*$B$10*(1+$B$6)^(E$14-1) -> 0 | F23: =F18*$B$10*(1+$B$6)^(F$14-1) -> 0 | G23: =G18*$B$10*(1+$B$6)^(G$14-1) -> 0 | H23: =H18*$B$10*(1+$B$6)^(H$14-1) -> 0 | I23: =I18*$B$10*(1+$B$6)^(I$14-1) -> 0 | J23: =J18*$B$10*(1+$B$6)^(J$14-1) -> 0 | K23: =K18*$B$10*(1+$B$6)^(K$14-1) -> 0 | L23: =SUM(B23:K23) -> 1045000 | M23: =L23/$K$26 -> 0.072243129
A24: Academic programmes - net operating ($) | B24: =B19*$B$11 -> 100000 | C24: =C19*$B$11*(1+$B$6)^(C$14-1) -> 218000 | D24: =D19*$B$11*(1+$B$6)^(D$14-1) -> 237620 | E24: =E19*$B$11*(1+$B$6)^(E$14-1) -> 259005.8 | F24: =F19*$B$11*(1+$B$6)^(F$14-1) -> 282316.32 | G24: =G19*$B$11*(1+$B$6)^(G$14-1) -> 307724.79 | H24: =H19*$B$11*(1+$B$6)^(H$14-1) -> 335420.02 | I24: =I19*$B$11*(1+$B$6)^(I$14-1) -> 365607.82 | J24: =J19*$B$11*(1+$B$6)^(J$14-1) -> 398512.53 | K24: =K19*$B$11*(1+$B$6)^(K$14-1) -> 434378.66 | L24: =SUM(B24:K24) -> 2938585.9 | M24: =L24/$K$26 -> 0.20315086
A25: Annual Cost (including escalation) | B25: =SUM(B21:B24) -> 5751250 | C25: =SUM(C21:C24) -> 1127966.1 | D25: =SUM(D21:D24) -> 645378.33 | E25: =SUM(E21:E24) -> 714573.8 | F25: =SUM(F21:F24) -> 791299.67 | G25: =SUM(G21:G24) -> 876386.43 | H25: =SUM(H21:H24) -> 970757.24 | I25: =SUM(I21:I24) -> 1075438.3 | ... K25: =SUM(K21:K24) -> 1320422.9 | L25: =SUM(B25:K25) -> 14465043 | M25: =L25/$K$26 -> 1
A26: Running total Costs | B26: =B25 -> 5751250 | C26: =B26+C25 -> 6879216.1 | D26: =C26+D25 -> 7524594.4 | E26: =D26+E25 -> 8239168.2 | F26: =E26+F25 -> 9030467.9 | G26: =F26+G25 -> 9906854.3 | H26: =G26+H25 -> 10877612 | I26: =H26+I25 -> 11953050 | J26: =I26+J25 -> 13144621 | K26: =J26+K25 -> 14465043

Sheet CUA
A1: Annual population increase (%) | B1: =Summary!B8 -> 0.025
A2: Target cost/QALY (CET) | B2: 1600 | C2: ***Use GDP per capita in USD as the Cost Effectiveness Threshold (CET)
A4: Interventions | B4: Malaria | C4: Ischemic Heart D. | D4: Neonat. Disorders | E4: Diarrheal Dis. | F4: L. Resp. Infect. | G4: Total QALYs | H4: Running Total
A5: Potential Health Impact (QALYs) | B5: 368388 | C5: 151410 | D5: 888979 | E5: 424713 | F5: 328420 | G5: =SUM(B5:F5) -> 2161910 | I5: NOTE: obtain QALY figures from IHME for country of interest
A6: Lead time (years before benefit) | B6: 4 | C6: 4 | D6: 4 | E6: 4 | F6: 4
A7: Benefit realization (%) | B7: 0.05 | C7: 0.05 | D7: 0.05 | E7: 0.05 | F7: 0.05
A8: YEAR (QALYs):
A9: 1 | B9: =IF($A9>B$6,1,0)*B$7*B$5*(1+$B$1)^($A9-1) -> 0 | C9: =IF($A9>C$6,1,0)*C$7*C$5*(1+$B$1)^($A9-1) -> 0 | D9: =IF($A9>D$6,1,0)*D$7*D$5*(1+$B$1)^($A9-1) -> 0 | E9: =IF($A9>E$6,1,0)*E$7*E$5*(1+$B$1)^($A9-1) -> 0 | F9: =IF($A9>F$6,1,0)*F$7*F$5*(1+$B$1)^($A9-1) -> 0 | G9: =SUM(B9:F9) -> 0 | H9: =G9 -> 0
A10: 2 | B10: =IF($A10>B$6,1,0)*B$7*B$5*(1+$B$1)^($A10-1) -> 0 | C10: =IF($A10>C$6,1,0)*C$7*C$5*(1+$B$1)^($A10-1) -> 0 | D10: =IF($A10>D$6,1,0)*D$7*D$5*(1+$B$1)^($A10-1) -> 0 | E10: =IF($A10>E$6,1,0)*E$7*E$5*(1+$B$1)^($A10-1) -> 0 | F10: =IF($A10>F$6,1,0)*F$7*F$5*(1+$B$1)^($A10-1) -> 0 | G10: =SUM(B10:F10) -> 0 | H10: =H9+G10 -> 0
A11: 3 | B11: =IF($A11>B$6,1,0)*B$7*B$5*(1+$B$1)^($A11-1) -> 0 | C11: =IF($A11>C$6,1,0)*C$7*C$5*(1+$B$1)^($A11-1) -> 0 | D11: =IF($A11>D$6,1,0)*D$7*D$5*(1+$B$1)^($A11-1) -> 0 | E11: =IF($A11>E$6,1,0)*E$7*E$5*(1+$B$1)^($A11-1) -> 0 | F11: =IF($A11>F$6,1,0)*F$7*F$5*(1+$B$1)^($A11-1) -> 0 | G11: =SUM(B11:F11) -> 0 | H11: =H10+G11 -> 0
A12: 4 | B12: =IF($A12>B$6,1,0)*B$7*B$5*(1+$B$1)^($A12-1) -> 0 | C12: =IF($A12>C$6,1,0)*C$7*C$5*(1+$B$1)^($A12-1) -> 0 | D12: =IF($A12>D$6,1,0)*D$7*D$5*(1+$B$1)^($A12-1) -> 0 | E12: =IF($A12>E$6,1,0)*E$7*E$5*(1+$B$1)^($A12-1) -> 0 | F12: =IF($A12>F$6,1,0)*F$7*F$5*(1+$B$1)^($A12-1) -> 0 | G12: =SUM(B12:F12) -> 0 | H12: =H11+G12 -> 0
A13: 5 | B13: =IF($A13>B$6,1,0)*B$7*B$5*(1+$B$1)^($A13-1) -> 20331.571 | C13: =IF($A13>C$6,1,0)*C$7*C$5*(1+$B$1)^($A13-1) -> 8356.4155 | D13: =IF($A13>D$6,1,0)*D$7*D$5*(1+$B$1)^($A13-1) -> 49063.324 | E13: =IF($A13>E$6,1,0)*E$7*E$5*(1+$B$1)^($A13-1) -> 23440.184 | F13: =IF($A13>F$6,1,0)*F$7*F$5*(1+$B$1)^($A13-1) -> 18125.711 | G13: =SUM(B13:F13) -> 119317.21 | H13: =H12+G13 -> 119317.21
A14: 6 | B14: =IF($A14>B$6,1,0)*B$7*B$5*(1+$B$1)^($A14-1) -> 20839.86 | C14: =IF($A14>C$6,1,0)*C$7*C$5*(1+$B$1)^($A14-1) -> 8565.3259 | D14: =IF($A14>D$6,1,0)*D$7*D$5*(1+$B$1)^($A14-1) -> 50289.907 | E14: =IF($A14>E$6,1,0)*E$7*E$5*(1+$B$1)^($A14-1) -> 24026.189 | F14: =IF($A14>F$6,1,0)*F$7*F$5*(1+$B$1)^($A14-1) -> 18578.854 | G14: =SUM(B14:F14) -> 122300.14 | H14: =H13+G14 -> 241617.34
A15: 7 | B15: =IF($A15>B$6,1,0)*B$7*B$5*(1+$B$1)^($A15-1) -> 21360.857 | C15: =IF($A15>C$6,1,0)*C$7*C$5*(1+$B$1)^($A15-1) -> 8779.459 | D15: =IF($A15>D$6,1,0)*D$7*D$5*(1+$B$1)^($A15-1) -> 51547.155 | E15: =IF($A15>E$6,1,0)*E$7*E$5*(1+$B$1)^($A15-1) -> 24626.844 | F15: =IF($A15>F$6,1,0)*F$7*F$5*(1+$B$1)^($A15-1) -> 19043.326 | G15: =SUM(B15:F15) -> 125357.64 | H15: =H14+G15 -> 366974.98
A16: 8 | B16: =IF($A16>B$6,1,0)*B$7*B$5*(1+$B$1)^($A16-1) -> 21894.878 | C16: =IF($A16>C$6,1,0)*C$7*C$5*(1+$B$1)^($A16-1) -> 8998.9455 | D16: =IF($A16>D$6,1,0)*D$7*D$5*(1+$B$1)^($A16-1) -> 52835.834 | E16: =IF($A16>E$6,1,0)*E$7*E$5*(1+$B$1)^($A16-1) -> 25242.515 | F16: =IF($A16>F$6,1,0)*F$7*F$5*(1+$B$1)^($A16-1) -> 19519.409 | G16: =SUM(B16:F16) -> 128491.58 | H16: =H15+G16 -> 495466.56
